Workbook

Sheet Source
A1: Production
A2: All Rates are in Pieces | K2: B = BOX ONLY
A3: Production Packaging | K3: I = BTL + BX
A5: Item# | B5: Formula # | C5: Description | D5: UM | E5: New Shift / Rate | F5: Crew Size | G5: HAZ CLASS | H5: Pack Type | I5: Closure Type | J5: Insert | K5: Label ID | L5: Brand | M5: SDS | N5: BOTTLE LABEL | O5: Box Label
A10: 111905 | B10: 111901 | C10: TREND ES STRIPPER 5;PAIL | D10: PL | E10: 453.6 | F10: 1 | G10: 0 | H10: 9801UNWL - UN WHITE PL | I10: 9804UNW- WHITE | J10: 0 | K10: I | L10: MTX
A11: 104332AMZ | B11: 104301 | C11: AMAZON BASICS RINSE AID;32OZ 12PK/CS | D11: CS | E11: 693 | F11: 6 | G11: 0 | H11: 9923 - 9874 28/400 NAT | I11: 9948 - FLIP CAP | J11: 0 | K11: 0 | L11: AMAZON | N11: 200322 | O11: 714403
A12: 104330AMZ | B12: 104301 | C12: AMAZON BASICS RINSE AID;8OZ 30PK/CS | D12: CS | F12: 8 | I12: 9948 - FLIP CAP | L12: AMAZON
A13: 104250AMZ | B13: 104201 | C13: AMAZON BASICS DISH SOAP,;FRESH SCENT 50OZ 1PK/CS | D13: CS | E13: 5400 | F13: 14 | G13: 0 | H13: 9853 - 9854 28/400 PET | I13: 9948HS - FLIP CAP | J13: 0 | K13: 0 | L13: AMAZON | N13: 710104
A14: 103202AMZ | B14: 103201 | C14: AMAZON PRESTO! APC,;LAVENDER 32OZ 2PK/CS | D14: CS | E14: 1050 | F14: 6 | G14: 0 | H14: 9875 | I14: 9962 / 23106 | J14: 0 | K14: 0 | L14: AMAZON | N14: 200342
A15: 103302AMZ | B15: 103301 | C15: AMAZON PRESTO! APC,LEMON;32OZ 2PK/CS | D15: CS | E15: 1050 | F15: 6 | G15: 0 | H15: 9875 | I15: 9962 / 23106 | J15: 0 | K15: 0 | L15: AMAZON | N15: 200341
A16: 103402AMZ | B16: 103401 | C16: AMAZON PRESTO! MS CONC;LAVENDER 32OZ 2PK/CS | D16: CS | E16: 1050 | F16: 6 | G16: 0 | H16: 9875 | I16: 9962 | J16: 0 | K16: 0 | L16: AMAZON | N16: 200354
A17: 103602AMZ | B17: 103601 | C17: AMAZON PRESTO! MS CONC;LEMON 32OZ 2PK/CS | D17: CS | E17: 1050 | F17: 6 | G17: 0 | H17: 9875 | I17: 9962 | J17: 0 | K17: 0 | L17: AMAZON | N17: 200353
A18: 103730AMZ | B18: 103701 | C18: AMAZON PRESTO! DISH LAVENDER 30OZ 2PK | D18: CS | E18: 2050 | F18: 6 | G18: 0 | H18: 9828 | I18: 9948HS | J18: 0 | K18: 0 | L18: AMAZON | N18: 200344
A19: 103830AMZ | B19: 103801 | C19: AMAZON PRESTO! DISH LEMON 30OZ 2PK | D19: CS | E19: 2050 | F19: 6 | G19: 0 | H19: 9828 | I19: 9948HS | J19: 0 | K19: 0 | L19: AMAZON | N19: 200343
A20: 104230AMZ | B20: 104201 | C20: AMAZON BASICS DISH SOAP FRESH SCENT 30OZ 4PK | D20: CS | E20: 2448 | F20: 6 | G20: 0 | H20: 9828 | I20: 9948HS | J20: 0 | K20: 0 | L20: AMAZON | N20: 121001
A21: 104664AMZ | B21: 104601 | C21: AMAZON BASICS OXY FRESH;CARPET 64 OZ 1/CS | D21: CS | E21: 2184 | F21: 6 | L21: AMAZON | N21: 200313
A22: 1046646AMZ | B22: 104601 | C22: AMAZON BASICS OXY FRESH;CARPET 64 OZ 6/CS | D22: CS | E22: 756 | F22: 6 | K22: B | L22: AMAZON | N22: 200321
A23: 104764AMZ | B23: 104701 | C23: AMAZON BASICS PET STAIN;CARPET 64 OZ 1/CS | D23: CS | E23: 2184 | F23: 6 | L23: AMAZON | N23: 200311
A24: 1047646AMZ | B24: 104701 | C24: AMAZON BASICS PET STAIN;CARPET 64 OZ 6/CS | D24: CS | E24: 756 | F24: 6 | K24: B | L24: AMAZON | N24: 200311
A25: 105704SYM | B25: 105701 | C25: SERENADE HD KITCHEN DEGREASER 4/1 CS | D25: CS | E25: 1352.4 | F25: 4 | G25: LIMITED Q. | I25: 9965-SAFETY | J25: 0 | K25: B | L25: SERENADE | N25: 714308
A26: 105002 | B26: 105001 | C26: SANITIZER DISINFECTANT 2/1 | D26: CS | E26: 1680 | F26: 5 | G26: 0 | L26: COSTCO | N26: 712105
A27: 105204SYM | B27: 105201 | C27: SERENADE TAHOE BLUE MS CLEANER 4/1 | D27: CS | E27: 1352.4 | F27: 4 | G27: 0 | K27: B | L27: SERENADE | N27: 714307
A28: 105504 | B28: 105501 | C28: LVT FLOOR CLEANER 4/1CS | D28: CS | E28: 1352.4 | F28: 4 | G28: 0 | K28: B | L28: MTX | N28: 712103
A29: 106102AMZ | B29: 106101 | C29: AMAZON BASICS GLASS CLNR 32OZ 2PK/CS | D29: CS | E29: 3000 | F29: 8 | G29: 0 | K29: 0 | L29: AMAZON | N29: 200331
A30: 106167AMZ | B30: 106101 | C30: AMAZON BASICS GLASS CLNR 67.6OZ 6/CS | D30: CS | E30: 900 | F30: 8 | G30: 0 | K30: B | L30: AMAZON | N30: 200312
A31: 106232 | B31: 106201 | C31: NON ACID DISINFECTANT 12/1 | D31: CS | E31: 693 | F31: 4 | G31: 0 | L31: MTX
A32: 106504 | B32: 106501 | C32: DDC GENERAL DISINFECTAN;4/1 CS | D32: cs | E32: 1352.4 | G32: 0 | L32: MTX | N32: 712001 | O32: 712001
A33: 105904SYM | B33: 105901 | C33: SERENADE PURE FOAMING HAND SOAP 4/1 | D33: cs | E33: 1352.4 | G33: 0 | K33: B | L33: SERENADE | N33: 712004
A34: 102304SYM | B34: 102301 | C34: SM LEMONCELLO SOAP 4/1 | D34: CS | E34: 1352.4 | G34: 0 | K34: B | L34: SERENADE | N34: 714302
A35: 110502BCI | B35: 110501 | C35: BCI FLOOR CLEANER LAVALOSO 2/CS | D35: CS | E35: 900 | G35: 0 | H35: 9900 (BTL) // 9022 (BX) | I35: 99560-H.SEAL | J35: 90035 | K35: B | L35: BCI | N35: 714405
A36: 111004RP | B36: 111001 | C36: ROYAL FRAGRANCE FREE;HAND SOAP 4/1GL CS | D36: CS | E36: 1352.4 | G36: 0 | H36: 9919 - WHITE GALLON | I36: 9994-REGULAR | J36: 0 | K36: B | L36: ROYAL CORP | N36: 714207
A37: 111904 | B37: 111901 | C37: TREND ES STRIPPER;CS environmentally prefe | D37: CS | E37: 1352.4 | G37: 0 | H37: 9919 - WHITE GALLON | I37: 9994-REGULAR | J37: 0 | K37: B | L37: MTX | N37: 712406
A38: 112104 | B38: 112101 | C38: JUST RIGHT OVEN/GRLL;CLNR 4/1C | D38: CS | E38: 1352.4 | G38: COR-2 | H38: 9888 (WHITE) / 9932 (UN BOX) | I38: 9965-SAFETY | J38: 0 | K38: 0 | L38: MTX | N38: 712507 | O38: 713103
A39: 112155 | B39: 112101 | C39: JUST RIGHT OVEN/GRILL;CLNR 55G | D39: 55GL | E39: 42 | F39: 1 | G39: COR-2 | H39: 97010 - BLUE DRUM | I39: 99521 | J39: 0 | K39: I | L39: MTX
A40: 112204 | B40: 112201 | C40: FAST ACTION 4/1 CS; | D40: CS | E40: 1352.4 | G40: COR-6 | H40: 9888 (WHITE) / 9932 (UN BOX) | I40: 9965-SAFETY | J40: 0 | K40: 0 | L40: MTX | N40: 200123 | O40: 713004
A41: 112204SYM | B41: 112201 | C41: SERENADE DOS LOCOS OVEN GRILL 4/1 | D41: CS | E41: 1352.4 | G41: COR-6 | H41: 9888 (WHITE) / 9932 (UN BOX) | I41: 9965-SAFETY | J41: 0 | K41: B | L41: SERENADE | N41: 714308
A42: 112232 | B42: 112201 | C42: FAST ACTION 12/1 CS; | D42: CS | E42: 440 | G42: COR-6 | H42: 9083 UN - 98680 SHORT | I42: 99640-SAFETY | J42: 0 | K42: 0 | L42: MTX | N42: 120801 | O42: 713103
A43: 112232SYM | B43: 112201 | C43: SERENADE DOS LOCOS OVEN GRILL 12/1 | D43: CS | E43: 440 | G43: COR-6 | H43: 9083 UN - 98680 SHORT | I43: 99640-SAFETY | J43: 0 | K43: 0 | L43: SERENADE | N43: 714307
A44: 112232FUL | B44: 112201 | C44: GLISTEN BLING 12/1 | D44: CS | E44: 440 | G44: COR-6 | H44: 9083 UN - 98680 SHORT | I44: 99640-SAFETY | J44: 0 | K44: B | L44: FULTON | N44: 714203
A45: 112504 | B45: 112501 | C45: OVENSTRIP 4/1 CS; | D45: CS | E45: 1352.4 | G45: COR-6 | H45: 9888 WHITE / 9932 (BX) | I45: 9965-SAFETY | J45: 0 | K45: S | L45: MTX | N45: 712505
...

Sheet Conversion
A1: Item# | B1: Decsription | C1: Conversion | D1: UOM | E1: WC | F1: Pallet | G1: Conversion 2
A2: 102304SYM | B2: SYM LEMONCELLO HAND SOAP;4/1CS | C2: 1 | D2: CS | E2: 1 | F2: 48 | G2: 4
A3: 103202AMZ | B3: AMAZON PRESTO! APC,;LAVENDER 32OZ 2PK/CS | C3: 1 | D3: CS | E3: 2 | F3: 44 | G3: 0.5
A4: 103302AMZ | B4: AMAZON PRESTO! APC,LEMON;32OZ 2PK/CS | C4: 1 | D4: CS | E4: 2 | F4: 44 | G4: 0.5
A5: 103402AMZ | B5: AMAZON PRESTO! MS CONC;LAVENDER 32OZ 2PK/CS | C5: 1 | D5: CS | E5: 2 | F5: 44 | G5: 0.5
A6: 103602AMZ | B6: AMAZON PRESTO! MS CONC;LEMON 32OZ 2PK/CS | C6: 1 | D6: CS | E6: 2 | F6: 44 | G6: 0.5
A7: 103730AMZ | B7: AMAZON PRESTO! DISH;LAVENDER 30OZ 2PK/CS | C7: 1 | D7: CS | E7: 4 | F7: 120 | G7: 1.5
A8: 103830AMZ | B8: AMAZON PRESTO! DISH;LEMON 30OZ 2PK/CS | C8: 1 | D8: CS | E8: 4 | F8: 288 | G8: 0.46875
A9: 104230AMZ | B9: AMAZON BASICS DISH SOAP,;FRESH 30OZ 4PK/CS | C9: 0.95139 | D9: CS | E9: 4 | F9: 48 | G9: 0.95139
A10: 104250AMZ | B10: AMAZON BASICS DISH SOAP,;FRSH SCNT 50OZ SIOC | C10: 1 | D10: CS | E10: 4 | F10: 360 | G10: 0.4
A11: 104330AMZ | B11: AMAZON BASICS RINSE AID;8OZ 30PK/CS | C11: 1 | D11: CS | E11: 0 | F11: 1 | G11: 1
A12: 104332AMZ | B12: AMAZON BASICS RINSE AID;32OZ 12PK/CS | C12: 1 | D12: CS | E12: 2 | F12: 55 | G12: 3
A13: 1045102 | B13: RF FLOOR CLEANER NEUT PH;2/160 OZ CS # 1760073 | C13: 1 | D13: CS | E13: 3 | F13: 36 | G13: 2.5
A14: 104664AMZ | B14: AMAZON BASICS OXY FRESH;CARPET 64 OZ 1/CS | C14: 1 | D14: CS | E14: 3 | F14: 36 | G14: 0.5
A15: 1046646AMZ | B15: AMAZON BASICS OXY FRESH;CARPET 64 OZ 6/CS | C15: 1 | D15: CS | E15: 1 | F15: 48 | G15: 3 | H15: F
A16: 104764AMZ | B16: AMAZON BASICS PET STAIN;CARPET 64 OZ 1/CS | C16: 1 | D16: CS | E16: 3 | F16: 36 | G16: 0.5
A17: 1047646AMZ | B17: AMAZON BASICS PET STAIN;CARPET 64 OZ 6/CS | C17: 1 | D17: CS | E17: 1 | F17: 48 | G17: 3
A18: 105002 | B18: SANITIZER DISINFECTANT;2/1 GL CS # 1804411 | C18: 1 | D18: CS | E18: 1 | F18: 84 | G18: 2
A19: 105204SYM | B19: SERENADE TAHOE BLUE;MS CLEANER 4/1 CS | C19: 1 | D19: CS | E19: 1 | F19: 48 | G19: 4
A20: 105302 | B20: PINK LOTION HAND SOAP;2/1GL CS # 1801027 | C20: 1 | D20: CS | E20: 1 | F20: 48 | G20: 2
A21: 105504 | B21: LVT FLOOR CLEANER;4GL/CS | C21: 4 | D21: GL | E21: 6 | F21: 48 | G21: 4
A22: 105564T4 | B22: #10 LVT FLOOR CLEANER;4GPM 4/64OZ DILSOL | C22: 4 | D22: BT | E22: 3 | F22: 100 | G22: 2
A23: 105604SYM | B23: SERENADE SOFT&MILD FOAM;HAND SOAP 4/1 | C23: 1 | D23: CS | E23: 1 | F23: 48 | G23: 4
A24: 1056616SYM | B24: SERENADE SOFT&MILD FM;HAND SOAP16OZ6/1CS | C24: 1 | D24: CS | E24: 0 | F24: 1 | G24: 1
A25: 105704SYM | B25: SERENADE HD KITCHEN DEGR;4/1 CASE | C25: 1 | D25: CS | E25: 1 | F25: 48 | G25: 4
A26: 105804RX | B26: DUST RX FAUX PLANT;CLEANER 4/1GL CS | C26: 1 | D26: CS | E26: 0 | F26: 1 | G26: 1
A27: 105904SYM | B27: SERENADE PURE FOAMING;HAND SOAP 4/1 | C27: 1 | D27: CS | E27: 1 | F27: 48 | G27: 4
A28: 106102AMZ | B28: AMAZON BASICS GLASS CLNR;32OZ 2PK/CS | C28: 1 | D28: CS | E28: 0 | F28: 1 | G28: 0.5
A29: 106167AMZ | B29: AMAZON BASICS GLASS CLNR;67.6OZ 6/CS | C29: 1 | D29: CS | E29: 0 | F29: 1 | G29: 3.16
A30: 106232 | B30: NON ACID DISINFECTANT RR;12/1CS | C30: 12 | D30: QT | E30: 2 | F30: 44 | G30: 3
A31: 106504 | B31: DDC GENERAL DISINFECTANT;CLEANER DEODORIZER 4/1CS | C31: 4 | D31: GL | E31: 6 | F31: 48 | G31: 4
A32: 106564T1 | B32: #14 DDC GENERAL DISINFEC;4/64OZ DILSOL | C32: 1 | D32: CS | E32: 0 | F32: 1 | G32: 1
A33: 110264T1 | B33: #2 N-ACID RESTROOM C;4/64OZ DILSOL# 1GAL PER | C33: 4 | D33: BT | E33: 3 | F33: 100 | G33: 2
A34: 110364T1 | B34: #3 ENZYME CLEANER & DEOD;1GPM 4/64OZ DILSOL | C34: 4 | D34: BT | E34: 3 | F34: 100 | G34: 2
A35: 110464T1 | B35: #4 GLASS&MIR CLNR 1G;4/64OZ DILSOL# GLASS & M | C35: 4 | D35: BT | E35: 3 | F35: 100 | G35: 2
A36: 110502BCI | B36: BCI FLOOR CLEANER;LAVALOSO MS 2GL/CS | C36: 1 | D36: CS | E36: 3 | F36: 36 | G36: 2
A37: 110564T1 | B37: #5 MLTI-SURF CLNR 1G;4/64OZ DILSOL# MULTI-SUR | C37: 4 | D37: BT | E37: 3 | F37: 100 | G37: 2
A38: 110764T1 | B38: #7 LINEN FRESH DEODORANT;DILSOL 4/64OZ | C38: 4 | D38: BT | E38: 3 | F38: 100 | G38: 2
A39: 110932SYM | B39: SERENADE TRUMPET NON ACD;WASHROOM CLNR12/1CS | C39: 1 | D39: CS | E39: 2 | F39: 44 | G39: 3
A40: 111004RP | B40: ROYAL FRAGRANCE FREE;HAND SOAP 4/1GL CS | C40: 1 | D40: CS | E40: 1 | F40: 48 | G40: 4
...

Sheet WIP
A1: Production
A2: Item # | B2: Desc | C2: Standard Run | D2: Ave Run Size | E2: Average Time/hrs | F2: Product Category | G2: Special Req's | H2: Corrections | I2: Difficulty
A3: 11101 | B3: BASE HAND SOAP BULK | C3: 2032 | D3: 1760 | E3: 4.1 | F3: Base | G3: Min 500gl | H3: 0.09 | I3: 1 | K3: 429.26829 | L3: Clear | M3: No Fragrance
A4: 111001 | B4: FRAGRANCE FREE HD SP BULK | C4: 488 | D4: 436 | E4: 1.4 | F4: Soap | G4: - | H4: 0.03 | I4: 4 | K4: 311.42857 | L4: Clear | M4: No Fragrance
A5: 102301 | B5: LEMON GRASS HAND SOAP | C5: 1000 | D5: 800 | E5: 3 | F5: Soap | G5: Base Needed | H5: 0 | I5: 4 | K5: 266.66667 | L5: Clear | M5: Tuscan Blood Orange
A6: 105001 | B6: MTX PROFESSIONAL SANITIZER | C6: 2100 | D6: 2000 | E6: 2 | F6: Disinfectant | G6: - | H6: 0 | I6: 1 | K6: 1000 | L6: Red | M6: No Fragrance
A7: 105301 | B7: PINK LOTION SOAP BULK | C7: 5200 | D7: 5200 | E7: 4 | F7: Soap | G7: Min 900gl | H7: 0 | I7: 4 | K7: 1300 | L7: Pink | M7: 0
A8: 103201 | B8: AMZN PRESTO APC LAVENDER | C8: 960 | D8: 311 | E8: 2.6 | F8: All Purpose Cleaner | G8: - | H8: 0.31 | I8: 2 | K8: 119.61538 | L8: Clear | M8: Lavender
A9: 103301 | B9: AMZN PRESTO APC LEMON | C9: 960 | D9: 353 | E9: 2.3 | F9: All Purpose Cleaner | G9: - | H9: 0.4 | I9: 2 | K9: 153.47826 | L9: Clear | M9: Citrus
A10: 103401 | B10: AMZN PRESTO LAVENDER CONC | C10: 960 | D10: 261 | E10: 2.4 | F10: All Purpose Cleaner | G10: - | H10: 0.86 | I10: 2 | K10: 108.75 | L10: Clear | M10: Lavender
A11: 103601 | B11: AMZN PRESTO LEMON CONC | C11: 960 | D11: 239 | E11: 1.3 | F11: All Purpose Cleaner | G11: - | H11: 0.43 | I11: 2 | K11: 183.84615 | L11: 0 | M11: 0
A12: 103701 | B12: AMZN PRESTO DISH LAVENDER | C12: 960 | D12: 495 | E12: 6.6 | F12: Dish Soap | G12: MIn 500gl | H12: 0.5 | I12: 4 | K12: 75 | L12: 0 | M12: 0
A13: 103801 | B13: AMZN PRESTO DISH LEMON | C13: 960 | D13: 513 | E13: 6 | F13: Dish Soap | G13: MIn 500gl | H13: 0.79 | I13: 4 | K13: 85.5 | L13: Light Yellow | M13: Lemon
A14: 104201 | B14: AMZN BASICS DISH FRESH SCENT | C14: 2200 | D14: 2585 | E14: 5.6 | F14: Dish Soap | G14: Min 2000gl | H14: 0.29 | I14: 4 | K14: 461.60714 | L14: Blue | M14: Citrus
A15: 104501 | B15: RINSE FREE NEUTRAL PH FLOOR CLEANER | C15: 4950 | D15: 2836 | E15: 3.1 | F15: Floor Cleaner | G15: - | H15: 0.13 | I15: 2 | K15: 914.83871 | L15: Yellow | M15: Lemon
A16: 104601 | B16: AMAZON BASICS OXY FRESH SCENT CARPET CLEANER | C16: 960 | D16: 1000 | E16: 2 | F16: Carpet Care | G16: Tank 72 or 74 | H16: 0 | I16: 2 | K16: 500 | L16: Clear | M16: No Fragrance
A17: 104701 | B17: AMAZON BASICS PET STAIN & ODOR CARPET CLEANER | C17: 960 | D17: 1000 | E17: 2 | F17: Carpet Care | G17: - | H17: 0 | I17: 2 | K17: 500 | L17: Clear | M17: No Fragrance
A18: 105201 | B18: BLUE MS CLEANER BULK | C18: 960 | D18: 200 | E18: 2 | F18: Specialty Clnr | H18: 0 | I18: 3 | K18: 100 | L18: 0 | M18: 0
A19: 105501 | B19: LVT FLOOR CLEANER BULK | C19: 1000 | D19: 200 | E19: 2 | F19: Specialty Clnr | H19: 0 | I19: 3 | K19: 100 | L19: White Milk | M19: Fresh Scent
A20: 105601 | B20: HONEY DEW LIGHT FOAMING HS | C20: 576 | D20: 600 | E20: 2 | F20: Foam Hnd Soap | H20: 0 | I20: 2 | K20: 300 | L20: 0 | M20: 0
A21: 105701 | B21: SUPER JET KLEEN CLEAR | C21: 576 | D21: 600 | E21: 2 | F21: Liq Degreaser | H21: 0 | I21: 2 | K21: 300 | L21: Clear | M21: No Fragrance
A22: 11201 | B22: BASE G.R.S BULK | C22: 739 | D22: 605 | E22: 2.1 | F22: Base | H22: 0 | I22: 1 | K22: 288.09524 | L22: Clear | M22: 0
A23: 11301 | B23: BASE NEUTRAL CLNRS BULK | C23: 508 | D23: 447 | E23: 2.6 | F23: Base | H23: 0.18 | I23: 1 | K23: 171.92308 | L23: 0 | M23: 0
A24: 11401 | B24: BASE FOAMING HD SP BULK | C24: 461 | D24: 461 | E24: 3.5 | F24: Base | H24: 1 | I24: 1 | K24: 131.71429 | L24: 0 | M24: 0
A25: 11501 | B25: FRESH & CLEAN BASE BULK | C25: 960 | D25: 960 | E25: 3 | F25: Base | H25: 0 | I25: 3 | K25: 320 | L25: 0 | M25: 0
A26: 115001 | B26: PEARSON VIVID ALLKLEEN BULK | C26: 55 | D26: 55 | E26: 2.8 | F26: Specialty Clnr | G26: - | H26: 1 | I26: 3 | K26: 19.642857 | L26: 0 | M26: 0
A27: 11801 | B27: FLOOR FINISH 100% BULK | C27: 2400 | D27: 2417 | E27: 6 | F27: Base | H27: 0.2 | I27: 1 | K27: 402.83333 | L27: 0 | M27: 0
A28: 88100 | B28: MC - 28 BULK | C28: 100 | D28: 0 | E28: 1 | F28: Raw Material | G28: - | H28: 0 | I28: 1 | K28: 0 | L28: 0 | M28: 0
A29: 101001 | B29: CLEAN THAT POT BULK | C29: 521 | D29: 478 | E29: 4 | F29: Specialty Clnr | G29: - | H29: 0.16 | I29: 3 | K29: 119.5 | L29: Blue | M29: No Fragrance
A30: 101101 | B30: SAFE TILE & CHROME CLNR BULK | C30: 200 | D30: 216 | E30: 2.1 | F30: Specialty Clnr | G30: - | H30: 0.18 | I30: 3 | K30: 102.85714 | L30: 0 | M30: 0
A31: 101201 | B31: CITRUS D.C. BULK | C31: 634 | D31: 615 | E31: 3.3 | F31: Specialty Clnr | G31: - | H31: 0.06 | I31: 3 | K31: 186.36364 | L31: 0 | M31: 0
A32: 101202 | B32: FLASH-128 BULK | C32: 200 | D32: 0 | E32: 3 | F32: Specialty Clnr | G32: - | H32: 0 | I32: 3 | K32: 0 | L32: 0 | M32: 0
A33: 101301 | B33: SUPER-CLEAN-ORANGE BULK | C33: 200 | D33: 0 | E33: 3 | F33: Specialty Clnr | G33: - | H33: 0 | I33: 3 | K33: 0 | L33: 0 | M33: 0
A34: 101401 | B34: SPARKLE BRITE BULK | C34: 117 | D34: 117 | E34: 2.1 | F34: Glass Clnr | G34: - | H34: 0 | I34: 2 | K34: 55.714286 | L34: 0 | M34: 0
A35: 101501 | B35: BLAST-IT BULK | C35: 264 | D35: 252 | E35: 1.8 | F35: Specialty Clnr | G35: - | H35: 0.05 | I35: 3 | K35: 140 | L35: 0 | M35: 0
A36: 101601 | B36: COLOSSUS BULK | C36: 200 | D36: 0 | E36: 3 | F36: Specialty Clnr | G36: - | H36: 0 | I36: 3 | K36: 0 | L36: 0 | M36: 0
A37: 101801 | B37: VERSATILE DISINFECTANT BULK | C37: 298 | D37: 276 | E37: 3.5 | F37: Disinfectant | G37: * EPA * | H37: 0.25 | I37: 3 | K37: 78.857143 | L37: 0 | M37: 0
A38: 102001 | B38: EXTRACTOR BULK | C38: 200 | D38: 0 | E38: 3 | F38: Car Care | G38: - | H38: 0 | I38: 2 | K38: 0 | L38: 0 | M38: 0
A39: 102201 | B39: DIP-R-SPRAY BULK | C39: 125 | D39: 125 | E39: 2.9 | F39: Specialty Clnr | G39: - | H39: 0.5 | I39: 3 | K39: 43.103448 | L39: 0 | M39: 0
A40: 102401 | B40: PREFERED LIQUID HD SP BULK | C40: 150 | D40: 125 | E40: 5 | F40: Liq Hnd Soap | G40: - | H40: 0 | I40: 4 | K40: 25 | L40: 0 | M40: 0
...

Sheet Pack
A1: Item# | B1: Default Line# | C1: Pack Type | D1: Formula # | E1: Closure Type | F1: Gal Conversion | G1: Pallet Qty
A6: 102304SYM | B6: 1 | C6: 9919 | D6: 102301 | E6: 99560 | F6: 4 | G6: 48
A7: 103202AMZ | B7: 2 | C7: 9875 | D7: 103201 | E7: 9963 | F7: 0.5 | G7: 150
A8: 103302AMZ | B8: 2 | C8: 9875 | D8: 103301 | E8: 9963 | F8: 0.5 | G8: 150
A9: 103402AMZ | B9: 2 | C9: 9875 | D9: 103401 | E9: 9963 | F9: 0.5 | G9: 150
A10: 103602AMZ | B10: 2 | C10: 9875 | D10: 103601 | E10: 9963 | F10: 2 | G10: 150
A11: 103730AMZ | B11: 4 | C11: 9828 | D11: 103701 | E11: 9948HS | F11: 0.5 | G11: 288
A12: 103830AMZ | B12: 4 | C12: 9828 | D12: 103801 | E12: 9948HS | F12: 0.5 | G12: 288
A13: 104230AMZ | B13: 4 | C13: 9828 | D13: 104201 | E13: 9948HS | F13: 0.95 | G13: 144
A14: 104250AMZ | B14: 4 | C14: 9852 | D14: 104201 | E14: 9948HS | F14: 2.34 | G14: 360
A15: 104332AMZ | B15: 2 | C15: 9875 | D15: 104301 | E15: #N/A | F15: 3 | G15: 55
A16: 1045102 | B16: 3 | C16: 9890 | D16: 104501 | E16: 99560 | F16: 2.5 | G16: 84
A17: 104664AMZ | B17: 3 | C17: 98711 | D17: 104601 | E17: 99534 | F17: 0.5 | G17: 312
A18: 104764AMZ | B18: 3 | C18: 98711 | D18: 104701 | E18: 99534 | F18: 0.5 | G18: 312
A19: 105002 | B19: 1 | C19: 9888N | D19: 105001 | E19: 99560 | F19: 2 | G19: 84
A20: 105204SYM | B20: 1 | C20: 9919 | D20: 105201 | E20: 9965 | F20: 4 | G20: 48
A21: 105302 | B21: 1 | C21: 9888N | D21: 182401 | E21: 99560 | F21: 2 | G21: 84
A22: 105604SYM | B22: 1 | C22: 9919 | D22: 105601 | E22: 9965 | F22: 4 | G22: 48
A23: 105704SYM | B23: 1 | C23: 9919-LQ | D23: 105701 | E23: 99560 | F23: 4 | G23: 48
A24: 108904FUL | B24: 1 | C24: 9877 | D24: 180802 | E24: 99560 | F24: 1 | G24: 48
A25: 1102644T1BRDY | B25: 3 | C25: 98710 | D25: 143509 | E25: 99560 | F25: 0.5 | G25: 100
A26: 110264T1 | B26: 3 | C26: 98710 | D26: 143509 | E26: 99560 | F26: 0.5 | G26: 400
A27: 1103644T1BRDY | B27: 3 | C27: 98710 | D27: 110301 | E27: 99560 | F27: 0.5 | G27: 100
A28: 1103644T1COLE | B28: 3 | C28: 98710 | D28: 110301 | E28: 99560 | F28: 0.5 | G28: 100
A29: 110364T1 | B29: 3 | C29: 98710 | D29: 110301 | E29: 99560 | F29: 0.5 | G29: 400
A30: 110464T1 | B30: 3 | C30: 98710 | D30: 110401 | E30: 99560 | F30: 0.5 | G30: 400
A31: 110502BCI | B31: 3 | C31: 9916 | D31: 110501 | E31: 9965 | F31: 2 | G31: 60
A32: 1105644T1BRDY | B32: 3 | C32: 98710 | D32: 110501 | E32: 99560 | F32: 0.5 | G32: 400
A33: 110564T1 | B33: 3 | C33: 98710 | D33: 110501 | E33: 99560 | F33: 0.5 | G33: 400
A34: 110664T1 | B34: 3 | C34: 98710 | D34: 110601 | E34: 99590 | F34: 0.5 | G34: 400
A35: 110764T1 | B35: 3 | C35: 98710 | D35: 158001 | E35: 99590 | F35: 0.5 | G35: 400
A36: 110864T1 | B36: 3 | C36: 98710 | D36: 110801 | E36: 99590 | F36: 0.5 | G36: 100
A37: 110932SYM | B37: 2 | C37: 9872 | D37: 110901 | E37: #N/A | F37: 3 | G37: 55
A38: 111004RP | B38: 1 | C38: 9919 | D38: 111001 | E38: 99560 | F38: 4 | G38: 48
A39: 111904 | B39: 1 | C39: 9919 | D39: 111901 | E39: 99560 | F39: 4 | G39: 192
A40: 111904BRDY | B40: 1 | C40: 9919 | D40: 111901 | E40: 99560 | F40: 1 | G40: 48
A41: 111905 | B41: 5 | C41: 9801UNWL | D41: 111901 | E41: 9804UNW | F41: 5 | G41: 36
A42: 111905BRDY | B42: 5 | C42: 9801UNWL | D42: 111901 | E42: 9804UNW | F42: 5 | G42: 36
A43: 112055ICL | B43: Manual Fill | C43: 97010 | D43: 112001 | E43: 99521 | F43: 1 | G43: 55
A44: 112104 | B44: 1 | C44: 99430 | D44: 112101 | E44: 99560 | F44: 4 | G44: 192
...

Sheet 01-02 PM
B1: PRODUCTION SCHEDULE | I1: 46024 | Q1: =R1 -> 14.228483 | R1: =SUM(Q14+Q23+Q32+Q38+Q48+Q54+Q61) -> 14.228483 | S1: =IF(R1>12,"Schedule Full") -> Schedule Full | AD1: =AG1-1 -> 46023 | AG1: =I1 -> 46024 | AI1: =SUM(AD4,AG4) -> 8280 | AJ1: Gallons
AD2: 1 shift | AG2: 2 shift
A3: PRIORITY | B3: Alert: All liquids MUST be filtered! NO EXCEPTIONS! | AD3: =AD4/4 -> 1870 | AE3: =AE4/5 -> 2.7405046 | AG3: =AG4/4 -> 200 | AH3: =AH4/5 -> 0.81979341
B4: Description | C4: Sku# | D4: Ordered | E4: Formula # | F4: Brand | G4: LABEL | H4: ID | I4: Haz_Info | K4: Bottle Label | L4: Box Label | M4: BOTTLE LABEL LOCATION | N4: BOX LABEL LOCATION | U4: Time | V4: Family | W4: Item Family | X4: Fragrance | Y4: WIP | Z4: Name | AA4: Pack Type | AB4: Rate | AC4: Notes | AD4: =SUM(AD7:AD63) -> 7480 | AE4: =SUM(AE7:AE63) -> 13.702523 | AG4: =SUM(AG7:AG63) -> 800 | AH4: =SUM(AH7:AH63) -> 4.0989671
B6: Line #1 | O6: Shift Rate | P6: Hour Rate | Q6: Run Time
A7: A | B7: =iferror(vlookup(C7,Source!$A$10:$O$1488,3,0),"-") -> HI SUDS PLUS DISH SOAP;4/1 CS | C7: 18300490 | D7: 1200 | E7: =iferror(vlookup(C7,Source!$A$10:$O$1488,2,0),"-") -> 183002 | F7: =iferror(vlookup(C7,Source!$A$10:$O$1488,12,0),"-") -> INNOUT | G7: =IF(H7="B","BOX LABEL",+IF(AND(H7="I"),"IN HOUSE",+IF(AND(H7="S"),"SPECIAL",+IF(AND(H7="BP"),"BUG FREE",+IF(AND(H7="A"),"Pre Labeled","-"))))) -> - | H7: =iferror(vlookup(C7,Source!$A$10:$O$1488,11,0),"-") -> 0 | I7: =iferror(vlookup(C7,Source!$A$10:$O$1488,7,0),"-") -> 0 | J7: =IFERROR(_xlfn.FLOOR.MATH(VLOOKUP(C7, Conversion!$A$1:$G$1483,7,0)*D7*1.05,10),"-") -> 5040 | K7: =if(G7="in house",D7*4,+if(G7="bottle label",D7*4,+if(or(G7="bottle"),G7*4,0))) -> 0 | L7: =if(G7="box label",D7,+IF(or(G7="in house"),D7,+if(or(G7="special"),D7,0))) -> 0 | M7: =iferror(vlookup(C7,Source!$A$10:$O$1488,14,0),"-") -> 120901 | N7: =iferror(vlookup(C7,Source!$A$10:$O$1488,15,0),"-") -> 713006 | O7: =iferror(vlookup(C7,Source!$A$10:$O$1488,5,0),0) -> 1352.4 | P7: =if(O7>1,O7/7.67,"-") -> 176.32334 | Q7: =if(O7>0,D7/O7*7.67,0) -> 6.8056788 | U7: =IF(Q7=0,14,SUM(5)+SUM(Q7)) -> 11.805679 | V7: =IFERROR(VLOOKUP(E7,WIP!$A$1:$S$1478,6,0),"-") -> Dish Soap | W7: =IFERROR(VLOOKUP(E7,WIP!$A$1:$M$1478,12,0),"-") -> Blue | X7: =IFERROR(VLOOKUP(E7,WIP!$A$1:$M$1478,13,0),"-") -> Floral | Y7: =E7 -> 183002 | Z7: =IFERROR(VLOOKUP(E7,WIP!$A$1:$K$1478,2,0),"-") -> HI SUDS PLUS DISH SOAP BULK | AA7: =IFERROR(VLOOKUP(C7,Pack!$A$5:$G$1997,3,FALSE),"-") -> 9877 | AB7: =IFERROR(VLOOKUP(E7,WIP!$A$1:$K$1478,11,0),"-") -> 598.81356 | AC7: =IFERROR(VLOOKUP(E7,WIP!$A$1:$K$1478,7,0),"-") -> Min 900gl | AD7: =IF(U7<13,J7,0) -> 5040 | AE7: =IFERROR(AD7/AB7,"-") -> 8.4166431 | AG7: =IF(U7>13,J7,0) -> 0 | AH7: =IFERROR(AG7/AB7,0) -> 0
A8: B | B8: =iferror(vlookup(C8,Source!$A$10:$O$1488,3,0),"-") -> - | E8: =iferror(vlookup(C8,Source!$A$10:$O$1488,2,0),"-") -> - | F8: =iferror(vlookup(C8,Source!$A$10:$O$1488,12,0),"-") -> - | G8: =IF(H8="B","BOX LABEL",+IF(AND(H8="I"),"IN HOUSE",+IF(AND(H8="S"),"SPECIAL",+IF(AND(H8="BP"),"BUG FREE",+IF(AND(H8="A"),"Pre Labeled","-"))))) -> - | H8: =iferror(vlookup(C8,Source!$A$10:$O$1488,11,0),"-") -> - | I8: =iferror(vlookup(C8,Source!$A$10:$O$1488,7,0),"-") -> - | J8: =IFERROR(_xlfn.FLOOR.MATH(VLOOKUP(C8, Conversion!$A$1:$G$1483,7,0)*D8*1.05,10),"-") -> - | K8: =if(G8="in house",D8*4,+if(G8="bottle label",D8*4,+if(or(G8="bottle"),G8*4,0))) -> 0 | L8: =if(G8="box label",D8,+IF(or(G8="in house"),D8,+if(or(G8="special"),D8,0))) -> 0 | M8: =iferror(vlookup(C8,Source!$A$10:$O$1488,14,0),"-") -> - | N8: =iferror(vlookup(C8,Source!$A$10:$O$1488,15,0),"-") -> - | O8: =iferror(vlookup(C8,Source!$A$10:$O$1488,5,0),0) -> 0 | P8: =if(O8>1,O8/7.67,"-") -> - | Q8: =if(O8>0,D8/O8*7.67,0) -> 0 | U8: =SUM(0.5,Q8)+SUM(U7) -> 12.305679 | V8: =IFERROR(VLOOKUP(E8,WIP!$A$1:$S$1478,6,0),"-") -> - | W8: =IFERROR(VLOOKUP(E8,WIP!$A$1:$M$1478,12,0),"-") -> - | X8: =IFERROR(VLOOKUP(E8,WIP!$A$1:$M$1478,13,0),"-") -> - | Y8: =E8 -> - | Z8: =IFERROR(VLOOKUP(E8,WIP!$A$1:$K$1478,2,0),"-") -> - | AA8: =IFERROR(VLOOKUP(C8,Pack!$A$5:$G$1997,3,FALSE),"-") -> - | AB8: =IFERROR(VLOOKUP(E8,WIP!$A$1:$K$1478,11,0),"-") -> - | AC8: =IFERROR(VLOOKUP(E8,WIP!$A$1:$K$1478,7,0),"-") -> - | AD8: =IF(U8<13,J8,0) -> - | AE8: =IFERROR(AD8/AB8,"-") -> - | AG8: =IF(U8>13,J8,0) -> 0 | AH8: =IFERROR(AG8/AB8,0) -> 0
A9: C | B9: =iferror(vlookup(C9,Source!$A$10:$O$1488,3,0),"-") -> - | E9: =iferror(vlookup(C9,Source!$A$10:$O$1488,2,0),"-") -> - | F9: =iferror(vlookup(C9,Source!$A$10:$O$1488,12,0),"-") -> - | G9: =IF(H9="B","BOX LABEL",+IF(AND(H9="I"),"IN HOUSE",+IF(AND(H9="S"),"SPECIAL",+IF(AND(H9="BP"),"BUG FREE",+IF(AND(H9="A"),"Pre Labeled","-"))))) -> - | H9: =iferror(vlookup(C9,Source!$A$10:$O$1488,11,0),"-") -> - | I9: =iferror(vlookup(C9,Source!$A$10:$O$1488,7,0),"-") -> - | J9: =IFERROR(_xlfn.FLOOR.MATH(VLOOKUP(C9, Conversion!$A$1:$G$1483,7,0)*D9*1.05,10),"-") -> - | K9: =if(G9="in house",D9*4,+if(G9="bottle label",D9*4,+if(or(G9="bottle"),G9*4,0))) -> 0 | L9: =if(G9="box label",D9,+IF(or(G9="in house"),D9,+if(or(G9="special"),D9,0))) -> 0 | M9: =iferror(vlookup(C9,Source!$A$10:$O$1488,14,0),"-") -> - | N9: =iferror(vlookup(C9,Source!$A$10:$O$1488,15,0),"-") -> - | O9: =iferror(vlookup(C9,Source!$A$10:$O$1488,5,0),0) -> 0 | P9: =if(O9>1,O9/7.67,"-") -> - | Q9: =if(O9>0,D9/O9*7.67,0) -> 0 | U9: =SUM(0.5,Q9)+SUM(U8) -> 12.805679 | V9: =IFERROR(VLOOKUP(E9,WIP!$A$1:$S$1478,6,0),"-") -> - | W9: =IFERROR(VLOOKUP(E9,WIP!$A$1:$M$1478,12,0),"-") -> - | X9: =IFERROR(VLOOKUP(E9,WIP!$A$1:$M$1478,13,0),"-") -> - | Y9: =E9 -> - | Z9: =IFERROR(VLOOKUP(E9,WIP!$A$1:$K$1478,2,0),"-") -> - | AA9: =IFERROR(VLOOKUP(C9,Pack!$A$5:$G$1997,3,FALSE),"-") -> - | AB9: =IFERROR(VLOOKUP(E9,WIP!$A$1:$K$1478,11,0),"-") -> - | AC9: =IFERROR(VLOOKUP(E9,WIP!$A$1:$K$1478,7,0),"-") -> - | AD9: =IF(U9<13,J9,0) -> - | AE9: =IFERROR(AD9/AB9,"-") -> - | AG9: =IF(U9>13,J9,0) -> 0 | AH9: =IFERROR(AG9/AB9,0) -> 0
A10: D | B10: =iferror(vlookup(C10,Source!$A$10:$O$1488,3,0),"-") -> - | E10: =iferror(vlookup(C10,Source!$A$10:$O$1488,2,0),"-") -> - | F10: =iferror(vlookup(C10,Source!$A$10:$O$1488,12,0),"-") -> - | G10: =IF(H10="B","BOX LABEL",+IF(AND(H10="I"),"IN HOUSE",+IF(AND(H10="S"),"SPECIAL",+IF(AND(H10="BP"),"BUG FREE",+IF(AND(H10="A"),"Pre Labeled","-"))))) -> - | H10: =iferror(vlookup(C10,Source!$A$10:$O$1488,11,0),"-") -> - | I10: =iferror(vlookup(C10,Source!$A$10:$O$1488,7,0),"-") -> - | J10: =IFERROR(_xlfn.FLOOR.MATH(VLOOKUP(C10, Conversion!$A$1:$G$1483,7,0)*D10*1.05,10),"-") -> - | K10: =if(G10="in house",D10*4,+if(G10="bottle label",D10*4,+if(or(G10="bottle"),G10*4,0))) -> 0 | L10: =if(G10="box label",D10,+IF(or(G10="in house"),D10,+if(or(G10="special"),D10,0))) -> 0 | M10: =iferror(vlookup(C10,Source!$A$10:$O$1488,14,0),"-") -> - | N10: =iferror(vlookup(C10,Source!$A$10:$O$1488,15,0),"-") -> - | O10: =iferror(vlookup(C10,Source!$A$10:$O$1488,5,0),0) -> 0 | P10: =if(O10>1,O10/7.67,"-") -> - | Q10: =if(O10>0,D10/O10*7.67,0) -> 0 | U10: =SUM(0.5,Q10)+SUM(U9) -> 13.305679 | V10: =IFERROR(VLOOKUP(E10,WIP!$A$1:$S$1478,6,0),"-") -> - | W10: =IFERROR(VLOOKUP(E10,WIP!$A$1:$M$1478,12,0),"-") -> - | X10: =IFERROR(VLOOKUP(E10,WIP!$A$1:$M$1478,13,0),"-") -> - | Y10: =E10 -> - | Z10: =IFERROR(VLOOKUP(E10,WIP!$A$1:$K$1478,2,0),"-") -> - | AA10: =IFERROR(VLOOKUP(C10,Pack!$A$5:$G$1997,3,FALSE),"-") -> - | AB10: =IFERROR(VLOOKUP(E10,WIP!$A$1:$K$1478,11,0),"-") -> - | AC10: =IFERROR(VLOOKUP(E10,WIP!$A$1:$K$1478,7,0),"-") -> - | AD10: =IF(U10<13,J10,0) -> 0 | AE10: =IFERROR(AD10/AB10,"-") -> - | AG10: =IF(U10>13,J10,0) -> - | AH10: =IFERROR(AG10/AB10,0) -> 0
A11: E | B11: =iferror(vlookup(C11,Source!$A$10:$O$1488,3,0),"-") -> - | E11: =iferror(vlookup(C11,Source!$A$10:$O$1488,2,0),"-") -> - | F11: =iferror(vlookup(C11,Source!$A$10:$O$1488,12,0),"-") -> - | G11: =IF(H11="B","BOX LABEL",+IF(AND(H11="I"),"IN HOUSE",+IF(AND(H11="S"),"SPECIAL",+IF(AND(H11="BP"),"BUG FREE",+IF(AND(H11="A"),"Pre Labeled","-"))))) -> - | H11: =iferror(vlookup(C11,Source!$A$10:$O$1488,11,0),"-") -> - | I11: =iferror(vlookup(C11,Source!$A$10:$O$1488,7,0),"-") -> - | J11: =IFERROR(_xlfn.FLOOR.MATH(VLOOKUP(C11, Conversion!$A$1:$G$1483,7,0)*D11*1.05,10),"-") -> - | K11: =if(G11="in house",D11*4,+if(G11="bottle label",D11*4,+if(or(G11="bottle"),G11*4,0))) -> 0 | L11: =if(G11="box label",D11,+IF(or(G11="in house"),D11,+if(or(G11="special"),D11,0))) -> 0 | M11: =iferror(vlookup(C11,Source!$A$10:$O$1488,14,0),"-") -> - | N11: =iferror(vlookup(C11,Source!$A$10:$O$1488,15,0),"-") -> - | O11: =iferror(vlookup(C11,Source!$A$10:$O$1488,5,0),0) -> 0 | P11: =if(O11>1,O11/7.67,"-") -> - | Q11: =if(O11>0,D11/O11*7.67,0) -> 0 | U11: =SUM(0.5,Q11)+SUM(U10) -> 13.805679 | V11: =IFERROR(VLOOKUP(E11,WIP!$A$1:$S$1478,6,0),"-") -> - | W11: =IFERROR(VLOOKUP(E11,WIP!$A$1:$M$1478,12,0),"-") -> - | X11: =IFERROR(VLOOKUP(E11,WIP!$A$1:$M$1478,13,0),"-") -> - | Y11: =E11 -> - | Z11: =IFERROR(VLOOKUP(E11,WIP!$A$1:$K$1478,2,0),"-") -> - | AA11: =IFERROR(VLOOKUP(C11,Pack!$A$5:$G$1997,3,FALSE),"-") -> - | AB11: =IFERROR(VLOOKUP(E11,WIP!$A$1:$K$1478,11,0),"-") -> - | AC11: =IFERROR(VLOOKUP(E11,WIP!$A$1:$K$1478,7,0),"-") -> - | AD11: =IF(U11<13,J11,0) -> 0 | AE11: =IFERROR(AD11/AB11,"-") -> - | AG11: =IF(U11>13,J11,0) -> - | AH11: =IFERROR(AG11/AB11,0) -> 0
E12: =iferror(vlookup(C12,Source!$A$10:$O$1488,2,0),"-") -> - | F12: =iferror(vlookup(C12,Source!$A$10:$O$1488,12,0),"-") -> - | G12: =IF(H12="B","BOX LABEL",+IF(AND(H12="I"),"IN HOUSE",+IF(AND(H12="S"),"SPECIAL",+IF(AND(H12="BP"),"BUG FREE",+IF(AND(H12="A"),"Pre Labeled","-"))))) -> - | H12: =iferror(vlookup(C12,Source!$A$10:$O$1488,11,0),"-") -> - | I12: =iferror(vlookup(C12,Source!$A$10:$O$1488,7,0),"-") -> - | J12: =IFERROR(_xlfn.FLOOR.MATH(VLOOKUP(C12, Conversion!$A$1:$G$1483,7,0)*D12*1.05,10),"-") -> - | K12: =if(G12="in house",D12*4,+if(G12="bottle label",D12*4,+if(or(G12="bottle"),G12*4,0))) -> 0 | L12: =if(G12="box label",D12,+IF(or(G12="in house"),D12,+if(or(G12="special"),D12,0))) -> 0 | M12: =iferror(vlookup(C12,Source!$A$10:$O$1488,14,0),"-") -> - | N12: =iferror(vlookup(C12,Source!$A$10:$O$1488,15,0),"-") -> - | O12: =iferror(vlookup(C12,Source!$A$10:$O$1488,5,0),0) -> 0 | P12: =if(O12>1,O12/7.67,"-") -> - | Q12: =if(O12>0,D12/O12*7.67,0) -> 0 | U12: =SUM(0.5,Q12)+SUM(U11) -> 14.305679 | V12: =IFERROR(VLOOKUP(E12,WIP!$A$1:$S$1478,6,0),"-") -> - | W12: =IFERROR(VLOOKUP(E12,WIP!$A$1:$M$1478,12,0),"-") -> - | X12: =IFERROR(VLOOKUP(E12,WIP!$A$1:$M$1478,13,0),"-") -> - | Y12: =E12 -> - | Z12: =IFERROR(VLOOKUP(E12,WIP!$A$1:$K$1478,2,0),"-") -> - | AA12: =IFERROR(VLOOKUP(C12,Pack!$A$5:$G$1997,3,FALSE),"-") -> - | AB12: =IFERROR(VLOOKUP(E12,WIP!$A$1:$K$1478,11,0),"-") -> - | AC12: =IFERROR(VLOOKUP(E12,WIP!$A$1:$K$1478,7,0),"-") -> - | AD12: =IF(U12<13,J12,0) -> 0 | AE12: =IFERROR(AD12/AB12,"-") -> - | AG12: =IF(U12>13,J12,0) -> - | AH12: =IFERROR(AG12/AB12,0) -> 0
U13: =SUM(0.5,Q13)+SUM(U12) -> 14.805679 | V13: =IFERROR(VLOOKUP(E13,WIP!$A$1:$S$1478,6,0),"-") -> - | W13: =IFERROR(VLOOKUP(E13,WIP!$A$1:$M$1478,12,0),"-") -> - | X13: =IFERROR(VLOOKUP(E13,WIP!$A$1:$M$1478,13,0),"-") -> - | Y13: =E13 | Z13: =IFERROR(VLOOKUP(E13,WIP!$A$1:$K$1478,2,0),"-") -> - | AA13: =IFERROR(VLOOKUP(C13,Pack!$A$5:$G$1997,3,FALSE),"-") -> - | AB13: =IFERROR(VLOOKUP(E13,WIP!$A$1:$K$1478,11,0),"-") -> - | AC13: =IFERROR(VLOOKUP(E13,WIP!$A$1:$K$1478,7,0),"-") -> - | AD13: =IF(U13<13,J13,0) -> 0 | AE13: =IFERROR(AD13/AB13,"-") -> - | AG13: =IF(U13>13,J13,0) | AH13: =IFERROR(AG13/AB13,0) -> 0
O14: TOTAL HOURS: | Q14: =SUM(Q7:Q12) -> 6.8056788 | V14: =IFERROR(VLOOKUP(E14,WIP!$A$1:$S$1478,6,0),"-") -> - | W14: =IFERROR(VLOOKUP(E14,WIP!$A$1:$M$1478,12,0),"-") -> - | X14: =IFERROR(VLOOKUP(E14,WIP!$A$1:$M$1478,13,0),"-") -> - | Y14: =E14 | Z14: =IFERROR(VLOOKUP(E14,WIP!$A$1:$K$1478,2,0),"-") -> - | AA14: =IFERROR(VLOOKUP(C14,Pack!$A$5:$G$1997,3,FALSE),"-") -> - | AB14: =IFERROR(VLOOKUP(E14,WIP!$A$1:$K$1478,11,0),"-") -> - | AC14: =IFERROR(VLOOKUP(E14,WIP!$A$1:$K$1478,7,0),"-") -> - | AD14: =IF(U14<13,J14,0) | AE14: =IFERROR(AD14/AB14,"-") -> - | AG14: =IF(U14>13,J14,0) -> 0 | AH14: =IFERROR(AG14/AB14,0) -> 0
O15: IDLE HOURS | Q15: =24-Q14 -> 17.194321 | V15: =IFERROR(VLOOKUP(E15,WIP!$A$1:$S$1478,6,0),"-") -> - | W15: =IFERROR(VLOOKUP(E15,WIP!$A$1:$M$1478,12,0),"-") -> - | X15: =IFERROR(VLOOKUP(E15,WIP!$A$1:$M$1478,13,0),"-") -> - | Y15: =E15 | Z15: =IFERROR(VLOOKUP(E15,WIP!$A$1:$K$1478,2,0),"-") -> - | AA15: =IFERROR(VLOOKUP(C15,Pack!$A$5:$G$1997,3,FALSE),"-") -> - | AB15: =IFERROR(VLOOKUP(E15,WIP!$A$1:$K$1478,11,0),"-") -> - | AC15: =IFERROR(VLOOKUP(E15,WIP!$A$1:$K$1478,7,0),"-") -> - | AD15: =IF(U15<13,J15,0) | AE15: =IFERROR(AD15/AB15,"-") -> - | AG15: =IF(U15>13,J15,0) -> 0 | AH15: =IFERROR(AG15/AB15,0) -> 0
B16: Line #6 | V16: =IFERROR(VLOOKUP(E16,WIP!$A$1:$S$1478,6,0),"-") -> - | W16: =IFERROR(VLOOKUP(E16,WIP!$A$1:$M$1478,12,0),"-") -> - | X16: =IFERROR(VLOOKUP(E16,WIP!$A$1:$M$1478,13,0),"-") -> - | Y16: =E16 | Z16: =IFERROR(VLOOKUP(E16,WIP!$A$1:$K$1478,2,0),"-") -> - | AA16: =IFERROR(VLOOKUP(C16,Pack!$A$5:$G$1997,3,FALSE),"-") -> - | AB16: =IFERROR(VLOOKUP(E16,WIP!$A$1:$K$1478,11,0),"-") -> - | AC16: =IFERROR(VLOOKUP(E16,WIP!$A$1:$K$1478,7,0),"-") -> - | AD16: =IF(U16<13,J16,0) | AE16: =IFERROR(AD16/AB16,"-") -> - | AG16: =IF(U16>13,J16,0) -> 0 | AH16: =IFERROR(AG16/AB16,0) -> 0
A17: A | B17: =iferror(vlookup(C17,Source!$A$10:$O$1488,3,0),"-") -> - | E17: =iferror(vlookup(C17,Source!$A$10:$O$1488,2,0),"-") -> - | F17: =iferror(vlookup(C17,Source!$A$10:$O$1488,12,0),"-") -> - | G17: =IF(H17="B","BOX LABEL",+IF(AND(H17="I"),"IN HOUSE",+IF(AND(H17="S"),"SPECIAL",+IF(AND(H17="BP"),"BUG FREE",+IF(AND(H17="A"),"Pre Labeled","-"))))) -> - | H17: =iferror(vlookup(C17,Source!$A$10:$O$1488,11,0),"-") -> - | I17: =iferror(vlookup(C17,Source!$A$10:$O$1488,7,0),"-") -> - | J17: =IFERROR(_xlfn.FLOOR.MATH(VLOOKUP(C17, Conversion!$A$1:$G$1483,7,0)*D17*1.05,10),"-") -> - | K17: =if(G17="in house",D17*4,+if(G17="bottle label",D17*4,+if(or(G17="bottle"),G17*4,0))) -> 0 | L17: =if(G17="box label",D17,+IF(or(G17="in house"),D17,+if(or(G17="special"),D17,0))) -> 0 | M17: =iferror(vlookup(C17,Source!$A$10:$O$1488,14,0),"-") -> - | N17: =iferror(vlookup(C17,Source!$A$10:$O$1488,15,0),"-") -> - | O17: =iferror(vlookup(C17,Source!$A$10:$O$1488,5,0),0) -> 0 | P17: =if(O17>1,O17/6.5,"-") -> - | Q17: =if(O17>0,D17/O17*6.5,0) -> 0 | U17: =IF(Q17=0,14,SUM(5)+SUM(Q17)) -> 14 | V17: =IFERROR(VLOOKUP(E17,WIP!$A$1:$S$1478,6,0),"-") -> - | W17: =IFERROR(VLOOKUP(E17,WIP!$A$1:$M$1478,12,0),"-") -> - | X17: =IFERROR(VLOOKUP(E17,WIP!$A$1:$M$1478,13,0),"-") -> - | Y17: =E17 -> - | Z17: =IFERROR(VLOOKUP(E17,WIP!$A$1:$K$1478,2,0),"-") -> - | AA17: =IFERROR(VLOOKUP(C17,Pack!$A$5:$G$1997,3,FALSE),"-") -> - | AB17: =IFERROR(VLOOKUP(E17,WIP!$A$1:$K$1478,11,0),"-") -> - | AC17: =IFERROR(VLOOKUP(E17,WIP!$A$1:$K$1478,7,0),"-") -> - | AD17: =IF(U17<13,J17,0) -> 0 | AE17: =IFERROR(AD17/AB17,"-") -> - | AG17: =IF(U17>13,J17,0) -> - | AH17: =IFERROR(AG17/AB17,0) -> 0
A18: B | B18: =iferror(vlookup(C18,Source!$A$10:$O$1488,3,0),"-") -> SAFER C. #551 FOAMIN;4/1GL CS | C18: 184404 | D18: 96 | E18: =iferror(vlookup(C18,Source!$A$10:$O$1488,2,0),"-") -> 184401 | F18: =iferror(vlookup(C18,Source!$A$10:$O$1488,12,0),"-") -> MTX | G18: =IF(H18="B","BOX LABEL",+IF(AND(H18="I"),"IN HOUSE",+IF(AND(H18="S"),"SPECIAL",+IF(AND(H18="BP"),"BUG FREE",+IF(AND(H18="A"),"Pre Labeled","-"))))) -> BOX LABEL | H18: =iferror(vlookup(C18,Source!$A$10:$O$1488,11,0),"-") -> B | I18: =iferror(vlookup(C18,Source!$A$10:$O$1488,7,0),"-") -> 0 | J18: =IFERROR(_xlfn.FLOOR.MATH(VLOOKUP(C18, Conversion!$A$1:$G$1483,7,0)*D18*1.05,10),"-") -> 400 | K18: =if(G18="in house",D18*4,+if(G18="bottle label",D18*4,+if(or(G18="bottle"),G18*4,0))) -> 0 | L18: =if(G18="box label",D18,+IF(or(G18="in house"),D18,+if(or(G18="special"),D18,0))) -> 96 | M18: =iferror(vlookup(C18,Source!$A$10:$O$1488,14,0),"-") -> 712310 | N18: =iferror(vlookup(C18,Source!$A$10:$O$1488,15,0),"-") | O18: =iferror(vlookup(C18,Source!$A$10:$O$1488,5,0),0) -> 1352.4 | P18: =if(O18>1,O18/6.5,"-") -> 208.06154 | Q18: =if(O18>0,D18/O18*6.5,0) -> 0.46140195 | U18: =SUM(0.5,Q18)+SUM(U17) -> 14.961402 | V18: =IFERROR(VLOOKUP(E18,WIP!$A$1:$S$1478,6,0),"-") -> Liq Hnd Soap | W18: =IFERROR(VLOOKUP(E18,WIP!$A$1:$M$1478,12,0),"-") -> Green | X18: =IFERROR(VLOOKUP(E18,WIP!$A$1:$M$1478,13,0),"-") -> Floral | Y18: =E18 -> 184401 | Z18: =IFERROR(VLOOKUP(E18,WIP!$A$1:$K$1478,2,0),"-") -> SAFER C. #551 FOAMING BULK | AA18: =IFERROR(VLOOKUP(C18,Pack!$A$5:$G$1997,3,FALSE),"-") -> 9919 | AB18: =IFERROR(VLOOKUP(E18,WIP!$A$1:$K$1478,11,0),"-") -> 125.21739 | AC18: =IFERROR(VLOOKUP(E18,WIP!$A$1:$K$1478,7,0),"-") -> - | AD18: =IF(U18<13,J18,0) -> 0 | AE18: =IFERROR(AD18/AB18,"-") -> 0 | AG18: =IF(U18>13,J18,0) -> 400 | AH18: =IFERROR(AG18/AB18,0) -> 3.1944444
A19: C | B19: =iferror(vlookup(C19,Source!$A$10:$O$1488,3,0),"-") -> GLIMMER ALL PURP.CLN;4/1 GAL | C19: 121404 | D19: 96 | E19: =iferror(vlookup(C19,Source!$A$10:$O$1488,2,0),"-") -> 121401 | F19: =iferror(vlookup(C19,Source!$A$10:$O$1488,12,0),"-") -> MTX | G19: =IF(H19="B","BOX LABEL",+IF(AND(H19="I"),"IN HOUSE",+IF(AND(H19="S"),"SPECIAL",+IF(AND(H19="BP"),"BUG FREE",+IF(AND(H19="A"),"Pre Labeled","-"))))) -> BOX LABEL | H19: =iferror(vlookup(C19,Source!$A$10:$O$1488,11,0),"-") -> B | I19: =iferror(vlookup(C19,Source!$A$10:$O$1488,7,0),"-") -> 0 | J19: =IFERROR(_xlfn.FLOOR.MATH(VLOOKUP(C19, Conversion!$A$1:$G$1483,7,0)*D19*1.05,10),"-") -> 400 | K19: =if(G19="in house",D19*4,+if(G19="bottle label",D19*4,+if(or(G19="bottle"),G19*4,0))) -> 0 | L19: =if(G19="box label",D19,+IF(or(G19="in house"),D19,+if(or(G19="special"),D19,0))) -> 96 | M19: =iferror(vlookup(C19,Source!$A$10:$O$1488,14,0),"-") -> 712402 | N19: =iferror(vlookup(C19,Source!$A$10:$O$1488,15,0),"-") | O19: =iferror(vlookup(C19,Source!$A$10:$O$1488,5,0),0) -> 1352.4 | P19: =if(O19>1,O19/6.5,"-") -> 208.06154 | Q19: =if(O19>0,D19/O19*6.5,0) -> 0.46140195 | U19: =SUM(0.5,Q19)+SUM(U18) -> 15.922804 | V19: =IFERROR(VLOOKUP(E19,WIP!$A$1:$S$1478,6,0),"-") -> G.P. Cleaner | W19: =IFERROR(VLOOKUP(E19,WIP!$A$1:$M$1478,12,0),"-") -> Purple | X19: =IFERROR(VLOOKUP(E19,WIP!$A$1:$M$1478,13,0),"-") -> Lavender | Y19: =E19 -> 121401 | Z19: =IFERROR(VLOOKUP(E19,WIP!$A$1:$K$1478,2,0),"-") -> GLIMMER | AA19: =IFERROR(VLOOKUP(C19,Pack!$A$5:$G$1997,3,FALSE),"-") -> 9919 | AB19: =IFERROR(VLOOKUP(E19,WIP!$A$1:$K$1478,11,0),"-") -> 442.22222 | AC19: =IFERROR(VLOOKUP(E19,WIP!$A$1:$K$1478,7,0),"-") -> - | AD19: =IF(U19<13,J19,0) -> 0 | AE19: =IFERROR(AD19/AB19,"-") -> 0 | AG19: =IF(U19>13,J19,0) -> 400 | AH19: =IFERROR(AG19/AB19,0) -> 0.90452261
A20: D | B20: =iferror(vlookup(C20,Source!$A$10:$O$1488,3,0),"-") -> - | E20: =iferror(vlookup(C20,Source!$A$10:$O$1488,2,0),"-") -> - | F20: =iferror(vlookup(C20,Source!$A$10:$O$1488,12,0),"-") -> - | G20: =IF(H20="B","BOX LABEL",+IF(AND(H20="I"),"IN HOUSE",+IF(AND(H20="S"),"SPECIAL",+IF(AND(H20="BP"),"BUG FREE",+IF(AND(H20="A"),"Pre Labeled","-"))))) -> - | H20: =iferror(vlookup(C20,Source!$A$10:$O$1488,11,0),"-") -> - | I20: =iferror(vlookup(C20,Source!$A$10:$O$1488,7,0),"-") -> - | J20: =IFERROR(_xlfn.FLOOR.MATH(VLOOKUP(C20, Conversion!$A$1:$G$1483,7,0)*D20*1.05,10),"-") -> - | K20: =if(G20="in house",D20*4,+if(G20="bottle label",D20*4,+if(or(G20="bottle"),G20*4,0))) -> 0 | L20: =if(G20="box label",D20,+IF(or(G20="in house"),D20,+if(or(G20="special"),D20,0))) -> 0 | M20: =iferror(vlookup(C20,Source!$A$10:$O$1488,14,0),"-") -> - | N20: =iferror(vlookup(C20,Source!$A$10:$O$1488,15,0),"-") -> - | O20: =iferror(vlookup(C20,Source!$A$10:$O$1488,5,0),0) -> 0 | P20: =if(O20>1,O20/6.5,"-") -> - | Q20: =if(O20>0,D20/O20*6.5,0) -> 0 | U20: =SUM(0.5,Q20)+SUM(U19) -> 16.422804 | V20: =IFERROR(VLOOKUP(E20,WIP!$A$1:$S$1478,6,0),"-") -> - | W20: =IFERROR(VLOOKUP(E20,WIP!$A$1:$M$1478,12,0),"-") -> - | X20: =IFERROR(VLOOKUP(E20,WIP!$A$1:$M$1478,13,0),"-") -> - | Y20: =E20 -> - | Z20: =IFERROR(VLOOKUP(E20,WIP!$A$1:$K$1478,2,0),"-") -> - | AA20: =IFERROR(VLOOKUP(C20,Pack!$A$5:$G$1997,3,FALSE),"-") -> - | AB20: =IFERROR(VLOOKUP(E20,WIP!$A$1:$K$1478,11,0),"-") -> - | AC20: =IFERROR(VLOOKUP(E20,WIP!$A$1:$K$1478,7,0),"-") -> - | AD20: =IF(U20<13,J20,0) -> 0 | AE20: =IFERROR(AD20/AB20,"-") -> - | AG20: =IF(U20>13,J20,0) -> - | AH20: =IFERROR(AG20/AB20,0) -> 0
A21: E | B21: =iferror(vlookup(C21,Source!$A$10:$O$1488,3,0),"-") -> - | E21: =iferror(vlookup(C21,Source!$A$10:$O$1488,2,0),"-") -> - | F21: =iferror(vlookup(C21,Source!$A$10:$O$1488,12,0),"-") -> - | G21: =IF(H21="B","BOX LABEL",+IF(AND(H21="I"),"IN HOUSE",+IF(AND(H21="S"),"SPECIAL",+IF(AND(H21="BP"),"BUG FREE",+IF(AND(H21="A"),"Pre Labeled","-"))))) -> - | H21: =iferror(vlookup(C21,Source!$A$10:$O$1488,11,0),"-") -> - | I21: =iferror(vlookup(C21,Source!$A$10:$O$1488,7,0),"-") -> - | J21: =IFERROR(_xlfn.FLOOR.MATH(VLOOKUP(C21, Conversion!$A$1:$G$1483,7,0)*D21*1.05,10),"-") -> - | K21: =if(G21="in house",D21*4,+if(G21="bottle label",D21*4,+if(or(G21="bottle"),G21*4,0))) -> 0 | L21: =if(G21="box label",D21,+IF(or(G21="in house"),D21,+if(or(G21="special"),D21,0))) -> 0 | M21: =iferror(vlookup(C21,Source!$A$10:$O$1488,14,0),"-") -> - | N21: =iferror(vlookup(C21,Source!$A$10:$O$1488,15,0),"-") -> - | O21: =iferror(vlookup(C21,Source!$A$10:$O$1488,5,0),0) -> 0 | P21: =if(O21>1,O21/6.5,"-") -> - | Q21: =if(O21>0,D21/O21*6.5,0) -> 0 | U21: =SUM(0.5,Q21)+SUM(U20) -> 16.922804 | V21: =IFERROR(VLOOKUP(E21,WIP!$A$1:$S$1478,6,0),"-") -> - | W21: =IFERROR(VLOOKUP(E21,WIP!$A$1:$M$1478,12,0),"-") -> - | X21: =IFERROR(VLOOKUP(E21,WIP!$A$1:$M$1478,13,0),"-") -> - | Y21: =E21 -> - | Z21: =IFERROR(VLOOKUP(E21,WIP!$A$1:$K$1478,2,0),"-") -> - | AA21: =IFERROR(VLOOKUP(C21,Pack!$A$5:$G$1997,3,FALSE),"-") -> - | AB21: =IFERROR(VLOOKUP(E21,WIP!$A$1:$K$1478,11,0),"-") -> - | AC21: =IFERROR(VLOOKUP(E21,WIP!$A$1:$K$1478,7,0),"-") -> - | AD21: =IF(U21<13,J21,0) -> 0 | AE21: =IFERROR(AD21/AB21,"-") -> - | AG21: =IF(U21>13,J21,0) -> - | AH21: =IFERROR(AG21/AB21,0) -> 0
U22: =SUM(0.5,Q22)+SUM(U21) -> 17.422804 | V22: =IFERROR(VLOOKUP(E22,WIP!$A$1:$S$1478,6,0),"-") -> - | W22: =IFERROR(VLOOKUP(E22,WIP!$A$1:$M$1478,12,0),"-") -> - | X22: =IFERROR(VLOOKUP(E22,WIP!$A$1:$M$1478,13,0),"-") -> - | Y22: =E22 | Z22: =IFERROR(VLOOKUP(E22,WIP!$A$1:$K$1478,2,0),"-") -> - | AA22: =IFERROR(VLOOKUP(C22,Pack!$A$5:$G$1997,3,FALSE),"-") -> - | AB22: =IFERROR(VLOOKUP(E22,WIP!$A$1:$K$1478,11,0),"-") -> - | AC22: =IFERROR(VLOOKUP(E22,WIP!$A$1:$K$1478,7,0),"-") -> - | AD22: =IF(U22<13,J22,0) -> 0 | AE22: =IFERROR(AD22/AB22,"-") -> - | AG22: =IF(U22>13,J22,0) | AH22: =IFERROR(AG22/AB22,0) -> 0
J23: gl | O23: TOTAL HOURS: | Q23: =SUM(Q17:Q21) -> 0.9228039 | U23: =SUM(0.5,Q23)+SUM(U22) -> 18.845608 | V23: =IFERROR(VLOOKUP(E23,WIP!$A$1:$S$1478,6,0),"-") -> - | W23: =IFERROR(VLOOKUP(E23,WIP!$A$1:$M$1478,12,0),"-") -> - | X23: =IFERROR(VLOOKUP(E23,WIP!$A$1:$M$1478,13,0),"-") -> - | Y23: =E23 | Z23: =IFERROR(VLOOKUP(E23,WIP!$A$1:$K$1478,2,0),"-") -> - | AA23: =IFERROR(VLOOKUP(C23,Pack!$A$5:$G$1997,3,FALSE),"-") -> - | AB23: =IFERROR(VLOOKUP(E23,WIP!$A$1:$K$1478,11,0),"-") -> - | AC23: =IFERROR(VLOOKUP(E23,WIP!$A$1:$K$1478,7,0),"-") -> - | AE23: =IFERROR(AD23/AB23,"-") -> - | AG23: =IF(U23>13,J23,0) -> gl | AH23: =IFERROR(AG23/AB23,0) -> 0
O24: IDLE HOURS | Q24: =24-Q23 -> 23.077196 | V24: =IFERROR(VLOOKUP(E24,WIP!$A$1:$S$1478,6,0),"-") -> - | W24: =IFERROR(VLOOKUP(E24,WIP!$A$1:$M$1478,12,0),"-") -> - | X24: =IFERROR(VLOOKUP(E24,WIP!$A$1:$M$1478,13,0),"-") -> - | Y24: =E24 | Z24: =IFERROR(VLOOKUP(E24,WIP!$A$1:$K$1478,2,0),"-") -> - | AA24: =IFERROR(VLOOKUP(C24,Pack!$A$5:$G$1997,3,FALSE),"-") -> - | AB24: =IFERROR(VLOOKUP(E24,WIP!$A$1:$K$1478,11,0),"-") -> - | AC24: =IFERROR(VLOOKUP(E24,WIP!$A$1:$K$1478,7,0),"-") -> - | AD24: =IF(U24<13,J24,0) | AE24: =IFERROR(AD24/AB24,"-") -> - | AG24: =IF(U24>13,J24,0) -> 0 | AH24: =IFERROR(AG24/AB24,0) -> 0
B25: Line #2 | U25: =IF(Q25=0,14,SUM(5)+SUM(Q25)) -> 14 | V25: =IFERROR(VLOOKUP(E25,WIP!$A$1:$S$1478,6,0),"-") -> - | W25: =IFERROR(VLOOKUP(E25,WIP!$A$1:$M$1478,12,0),"-") -> - | X25: =IFERROR(VLOOKUP(E25,WIP!$A$1:$M$1478,13,0),"-") -> - | Y25: =E25 | Z25: =IFERROR(VLOOKUP(E25,WIP!$A$1:$K$1478,2,0),"-") -> - | AA25: =IFERROR(VLOOKUP(C25,Pack!$A$5:$G$1997,3,FALSE),"-") -> - | AB25: =IFERROR(VLOOKUP(E25,WIP!$A$1:$K$1478,11,0),"-") -> - | AC25: =IFERROR(VLOOKUP(E25,WIP!$A$1:$K$1478,7,0),"-") -> - | AD25: =IF(U25<13,J25,0) -> 0 | AE25: =IFERROR(AD25/AB25,"-") -> - | AG25: =IF(U25>13,J25,0) | AH25: =IFERROR(AG25/AB25,0) -> 0
A26: A | B26: =iferror(vlookup(C26,Source!$A$10:$O$1488,3,0),"-") -> - | E26: =iferror(vlookup(C26,Source!$A$10:$O$1488,2,0),"-") -> - | F26: =iferror(vlookup(C26,Source!$A$10:$O$1488,12,0),"-") -> - | G26: =IF(H26="B","BOX LABEL",+IF(AND(H26="I"),"IN HOUSE",+IF(AND(H26="S"),"SPECIAL",+IF(AND(H26="BP"),"BUG FREE",+IF(AND(H26="A"),"Pre Labeled","-"))))) -> - | H26: =iferror(vlookup(C26,Source!$A$10:$O$1488,11,0),"-") -> - | I26: =iferror(vlookup(C26,Source!$A$10:$O$1488,7,0),"-") -> - | J26: =IFERROR(_xlfn.FLOOR.MATH(VLOOKUP(C26, Conversion!$A$1:$G$1483,7,0)*D26*1.05,10),"-") -> - | K26: =if(G26="in house",D26*4,+if(G26="bottle label",D26*4,+if(or(G26="bottle"),G26*4,0))) -> 0 | L26: =if(G26="box label",D26,+IF(or(G26="in house"),D26,+if(or(G26="special"),D26,0))) -> 0 | M26: =iferror(vlookup(C26,Source!$A$10:$O$1488,14,0),"-") -> - | N26: =iferror(vlookup(C26,Source!$A$10:$O$1488,15,0),"-") -> - | O26: =iferror(vlookup(C26,Source!$A$10:$O$1488,5,0),0) -> 0 | P26: =if(O26>1,O26/6.5,"-") -> - | Q26: =if(O26>0,D26/O26*6.5,0) -> 0 | U26: =SUM(0.5,Q26)+SUM(U25) -> 14.5 | V26: =IFERROR(VLOOKUP(E26,WIP!$A$1:$S$1478,6,0),"-") -> - | W26: =IFERROR(VLOOKUP(E26,WIP!$A$1:$M$1478,12,0),"-") -> - | X26: =IFERROR(VLOOKUP(E26,WIP!$A$1:$M$1478,13,0),"-") -> - | Y26: =E26 -> - | Z26: =IFERROR(VLOOKUP(E26,WIP!$A$1:$K$1478,2,0),"-") -> - | AA26: =IFERROR(VLOOKUP(C26,Pack!$A$5:$G$1997,3,FALSE),"-") -> - | AB26: =IFERROR(VLOOKUP(E26,WIP!$A$1:$K$1478,11,0),"-") -> - | AC26: =IFERROR(VLOOKUP(E26,WIP!$A$1:$K$1478,7,0),"-") -> - | AD26: =IF(U26<13,J26,0) -> 0 | AE26: =IFERROR(AD26/AB26,"-") -> - | AG26: =IF(U26>13,J26,0) -> - | AH26: =IFERROR(AG26/AB26,0) -> 0
A27: B | B27: =iferror(vlookup(C27,Source!$A$10:$O$1488,3,0),"-") -> - | E27: =iferror(vlookup(C27,Source!$A$10:$O$1488,2,0),"-") -> - | F27: =iferror(vlookup(C27,Source!$A$10:$O$1488,12,0),"-") -> - | G27: =IF(H27="B","BOX LABEL",+IF(AND(H27="I"),"IN HOUSE",+IF(AND(H27="S"),"SPECIAL",+IF(AND(H27="BP"),"BUG FREE",+IF(AND(H27="A"),"Pre Labeled","-"))))) -> - | H27: =iferror(vlookup(C27,Source!$A$10:$O$1488,11,0),"-") -> - | I27: =iferror(vlookup(C27,Source!$A$10:$O$1488,7,0),"-") -> - | J27: =IFERROR(_xlfn.FLOOR.MATH(VLOOKUP(C27, Conversion!$A$1:$G$1483,7,0)*D27*1.05,10),"-") -> - | K27: =if(G27="in house",D27*4,+if(G27="bottle label",D27*4,+if(or(G27="bottle"),G27*4,0))) -> 0 | L27: =if(G27="box label",D27,+IF(or(G27="in house"),D27,+if(or(G27="special"),D27,0))) -> 0 | M27: =iferror(vlookup(C27,Source!$A$10:$O$1488,14,0),"-") -> - | N27: =iferror(vlookup(C27,Source!$A$10:$O$1488,15,0),"-") -> - | O27: =iferror(vlookup(C27,Source!$A$10:$O$1488,5,0),0) -> 0 | P27: =if(O27>1,O27/6.5,"-") -> - | Q27: =if(O27>0,D27/O27*6.5,0) -> 0 | U27: =SUM(0.5,Q27)+SUM(U26) -> 15 | V27: =IFERROR(VLOOKUP(E27,WIP!$A$1:$S$1478,6,0),"-") -> - | W27: =IFERROR(VLOOKUP(E27,WIP!$A$1:$M$1478,12,0),"-") -> - | X27: =IFERROR(VLOOKUP(E27,WIP!$A$1:$M$1478,13,0),"-") -> - | Y27: =E27 -> - | Z27: =IFERROR(VLOOKUP(E27,WIP!$A$1:$K$1478,2,0),"-") -> - | AA27: =IFERROR(VLOOKUP(C27,Pack!$A$5:$G$1997,3,FALSE),"-") -> - | AB27: =IFERROR(VLOOKUP(E27,WIP!$A$1:$K$1478,11,0),"-") -> - | AC27: =IFERROR(VLOOKUP(E27,WIP!$A$1:$K$1478,7,0),"-") -> - | AD27: =IF(U27<13,J27,0) -> 0 | AE27: =IFERROR(AD27/AB27,"-") -> - | AG27: =IF(U27>13,J27,0) -> - | AH27: =IFERROR(AG27/AB27,0) -> 0
A28: C | B28: =iferror(vlookup(C28,Source!$A$10:$O$1488,3,0),"-") -> - | E28: =iferror(vlookup(C28,Source!$A$10:$O$1488,2,0),"-") -> - | F28: =iferror(vlookup(C28,Source!$A$10:$O$1488,12,0),"-") -> - | G28: =IF(H28="B","BOX LABEL",+IF(AND(H28="I"),"IN HOUSE",+IF(AND(H28="S"),"SPECIAL",+IF(AND(H28="BP"),"BUG FREE",+IF(AND(H28="A"),"Pre Labeled","-"))))) -> - | H28: =iferror(vlookup(C28,Source!$A$10:$O$1488,11,0),"-") -> - | I28: =iferror(vlookup(C28,Source!$A$10:$O$1488,7,0),"-") -> - | J28: =IFERROR(_xlfn.FLOOR.MATH(VLOOKUP(C28, Conversion!$A$1:$G$1483,7,0)*D28*1.05,10),"-") -> - | K28: =if(G28="in house",D28*4,+if(G28="bottle label",D28*4,+if(or(G28="bottle"),G28*4,0))) -> 0 | L28: =if(G28="box label",D28,+IF(or(G28="in house"),D28,+if(or(G28="special"),D28,0))) -> 0 | M28: =iferror(vlookup(C28,Source!$A$10:$O$1488,14,0),"-") -> - | N28: =iferror(vlookup(C28,Source!$A$10:$O$1488,15,0),"-") -> - | O28: =iferror(vlookup(C28,Source!$A$10:$O$1488,5,0),0) -> 0 | P28: =if(O28>1,O28/6.5,"-") -> - | Q28: =if(O28>0,D28/O28*6.5,0) -> 0 | U28: =SUM(0.5,Q28)+SUM(U27) -> 15.5 | V28: =IFERROR(VLOOKUP(E28,WIP!$A$1:$S$1478,6,0),"-") -> - | W28: =IFERROR(VLOOKUP(E28,WIP!$A$1:$M$1478,12,0),"-") -> - | X28: =IFERROR(VLOOKUP(E28,WIP!$A$1:$M$1478,13,0),"-") -> - | Y28: =E28 -> - | Z28: =IFERROR(VLOOKUP(E28,WIP!$A$1:$K$1478,2,0),"-") -> - | AA28: =IFERROR(VLOOKUP(C28,Pack!$A$5:$G$1997,3,FALSE),"-") -> - | AB28: =IFERROR(VLOOKUP(E28,WIP!$A$1:$K$1478,11,0),"-") -> - | AC28: =IFERROR(VLOOKUP(E28,WIP!$A$1:$K$1478,7,0),"-") -> - | AD28: =IF(U28<13,J28,0) -> 0 | AE28: =IFERROR(AD28/AB28,"-") -> - | AG28: =IF(U28>13,J28,0) -> - | AH28: =IFERROR(AG28/AB28,0) -> 0
A29: D | B29: =iferror(vlookup(C29,Source!$A$10:$O$1488,3,0),"-") -> - | E29: =iferror(vlookup(C29,Source!$A$10:$O$1488,2,0),"-") -> - | F29: =iferror(vlookup(C29,Source!$A$10:$O$1488,12,0),"-") -> - | G29: =IF(H29="B","BOX LABEL",+IF(AND(H29="I"),"IN HOUSE",+IF(AND(H29="S"),"SPECIAL",+IF(AND(H29="BP"),"BUG FREE",+IF(AND(H29="A"),"Pre Labeled","-"))))) -> - | H29: =iferror(vlookup(C29,Source!$A$10:$O$1488,11,0),"-") -> - | I29: =iferror(vlookup(C29,Source!$A$10:$O$1488,7,0),"-") -> - | J29: =IFERROR(_xlfn.FLOOR.MATH(VLOOKUP(C29, Conversion!$A$1:$G$1483,7,0)*D29*1.05,10),"-") -> - | K29: =if(G29="in house",D29*4,+if(G29="bottle label",D29*4,+if(or(G29="bottle"),G29*4,0))) -> 0 | L29: =if(G29="box label",D29,+IF(or(G29="in house"),D29,+if(or(G29="special"),D29,0))) -> 0 | M29: =iferror(vlookup(C29,Source!$A$10:$O$1488,14,0),"-") -> - | N29: =iferror(vlookup(C29,Source!$A$10:$O$1488,15,0),"-") -> - | O29: =iferror(vlookup(C29,Source!$A$10:$O$1488,5,0),0) -> 0 | P29: =if(O29>1,O29/6.5,"-") -> - | Q29: =if(O29>0,D29/O29*6.5,0) -> 0 | U29: =SUM(0.5,Q29)+SUM(U28) -> 16 | V29: =IFERROR(VLOOKUP(E29,WIP!$A$1:$S$1478,6,0),"-") -> - | W29: =IFERROR(VLOOKUP(E29,WIP!$A$1:$M$1478,12,0),"-") -> - | X29: =IFERROR(VLOOKUP(E29,WIP!$A$1:$M$1478,13,0),"-") -> - | Y29: =E29 -> - | Z29: =IFERROR(VLOOKUP(E29,WIP!$A$1:$K$1478,2,0),"-") -> - | AA29: =IFERROR(VLOOKUP(C29,Pack!$A$5:$G$1997,3,FALSE),"-") -> - | AB29: =IFERROR(VLOOKUP(E29,WIP!$A$1:$K$1478,11,0),"-") -> - | AC29: =IFERROR(VLOOKUP(E29,WIP!$A$1:$K$1478,7,0),"-") -> - | AD29: =IF(U29<13,J29,0) -> 0 | AE29: =IFERROR(AD29/AB29,"-") -> - | AG29: =IF(U29>13,J29,0) -> - | AH29: =IFERROR(AG29/AB29,0) -> 0
A30: E | B30: =iferror(vlookup(C30,Source!$A$10:$O$1488,3,0),"-") -> - | E30: =iferror(vlookup(C30,Source!$A$10:$O$1488,2,0),"-") -> - | F30: =iferror(vlookup(C30,Source!$A$10:$O$1488,12,0),"-") -> - | G30: =IF(H30="B","BOX LABEL",+IF(AND(H30="I"),"IN HOUSE",+IF(AND(H30="S"),"SPECIAL",+IF(AND(H30="BP"),"BUG FREE",+IF(AND(H30="A"),"Pre Labeled","-"))))) -> - | H30: =iferror(vlookup(C30,Source!$A$10:$O$1488,11,0),"-") -> - | I30: =iferror(vlookup(C30,Source!$A$10:$O$1488,7,0),"-") -> - | K30: =if(G30="in house",D30*4,+if(G30="bottle label",D30*4,+if(or(G30="bottle"),G30*4,0))) -> 0 | L30: =if(G30="box label",D30,+IF(or(G30="in house"),D30,+if(or(G30="special"),D30,0))) -> 0 | M30: =iferror(vlookup(C30,Source!$A$10:$O$1488,14,0),"-") -> - | N30: =iferror(vlookup(C30,Source!$A$10:$O$1488,15,0),"-") -> - | O30: =iferror(vlookup(C30,Source!$A$10:$O$1488,5,0),0) -> 0 | P30: =if(O30>1,O30/6.5,"-") -> - | Q30: =if(O30>0,D30/O30*6.5,0) -> 0 | U30: =SUM(0.5,Q30)+SUM(U29) -> 16.5 | V30: =IFERROR(VLOOKUP(E30,WIP!$A$1:$S$1478,6,0),"-") -> - | W30: =IFERROR(VLOOKUP(E30,WIP!$A$1:$M$1478,12,0),"-") -> - | X30: =IFERROR(VLOOKUP(E30,WIP!$A$1:$M$1478,13,0),"-") -> - | Y30: =E30 -> - | Z30: =IFERROR(VLOOKUP(E30,WIP!$A$1:$K$1478,2,0),"-") -> - | AA30: =IFERROR(VLOOKUP(C30,Pack!$A$5:$G$1997,3,FALSE),"-") -> - | AB30: =IFERROR(VLOOKUP(E30,WIP!$A$1:$K$1478,11,0),"-") -> - | AC30: =IFERROR(VLOOKUP(E30,WIP!$A$1:$K$1478,7,0),"-") -> - | AD30: =IF(U30<13,J30,0) -> 0 | AE30: =IFERROR(AD30/AB30,"-") -> - | AG30: =IF(U30>13,J30,0) | AH30: =IFERROR(AG30/AB30,0) -> 0
U31: =SUM(0.5,Q31)+SUM(U30) -> 17 | V31: =IFERROR(VLOOKUP(E31,WIP!$A$1:$S$1478,6,0),"-") -> - | W31: =IFERROR(VLOOKUP(E31,WIP!$A$1:$M$1478,12,0),"-") -> - | X31: =IFERROR(VLOOKUP(E31,WIP!$A$1:$M$1478,13,0),"-") -> - | Y31: =E31 | Z31: =IFERROR(VLOOKUP(E31,WIP!$A$1:$K$1478,2,0),"-") -> - | AA31: =IFERROR(VLOOKUP(C31,Pack!$A$5:$G$1997,3,FALSE),"-") -> - | AB31: =IFERROR(VLOOKUP(E31,WIP!$A$1:$K$1478,11,0),"-") -> - | AC31: =IFERROR(VLOOKUP(E31,WIP!$A$1:$K$1478,7,0),"-") -> - | AD31: =IF(U31<13,J31,0) -> 0 | AE31: =IFERROR(AD31/AB31,"-") -> - | AG31: =IF(U31>13,J31,0) | AH31: =IFERROR(AG31/AB31,0) -> 0
J32: gl | O32: TOTAL HOURS: | Q32: =SUM(Q26:Q30) -> 0 | V32: =IFERROR(VLOOKUP(E32,WIP!$A$1:$S$1478,6,0),"-") -> - | W32: =IFERROR(VLOOKUP(E32,WIP!$A$1:$M$1478,12,0),"-") -> - | X32: =IFERROR(VLOOKUP(E32,WIP!$A$1:$M$1478,13,0),"-") -> - | Y32: =E32 | Z32: =IFERROR(VLOOKUP(E32,WIP!$A$1:$K$1478,2,0),"-") -> - | AA32: =IFERROR(VLOOKUP(C32,Pack!$A$5:$G$1997,3,FALSE),"-") -> - | AB32: =IFERROR(VLOOKUP(E32,WIP!$A$1:$K$1478,11,0),"-") -> - | AC32: =IFERROR(VLOOKUP(E32,WIP!$A$1:$K$1478,7,0),"-") -> - | AE32: =IFERROR(AD32/AB32,"-") -> - | AG32: =IF(U32>13,J32,0) -> 0 | AH32: =IFERROR(AG32/AB32,0) -> 0
O33: IDLE HOURS | Q33: =24-Q32 -> 24 | V33: =IFERROR(VLOOKUP(E33,WIP!$A$1:$S$1478,6,0),"-") -> - | W33: =IFERROR(VLOOKUP(E33,WIP!$A$1:$M$1478,12,0),"-") -> - | X33: =IFERROR(VLOOKUP(E33,WIP!$A$1:$M$1478,13,0),"-") -> - | Y33: =E33 | Z33: =IFERROR(VLOOKUP(E33,WIP!$A$1:$K$1478,2,0),"-") -> - | AA33: =IFERROR(VLOOKUP(C33,Pack!$A$5:$G$1997,3,FALSE),"-") -> - | AB33: =IFERROR(VLOOKUP(E33,WIP!$A$1:$K$1478,11,0),"-") -> - | AC33: =IFERROR(VLOOKUP(E33,WIP!$A$1:$K$1478,7,0),"-") -> - | AD33: =IF(U33<13,J33,0) | AE33: =IFERROR(AD33/AB33,"-") -> - | AG33: =IF(U33>13,J33,0) -> 0 | AH33: =IFERROR(AG33/AB33,0) -> 0
B34: Line #7 | U34: =IF(Q34=0,14,SUM(5)+SUM(Q34)) -> 14 | V34: =IFERROR(VLOOKUP(E34,WIP!$A$1:$S$1478,6,0),"-") -> - | W34: =IFERROR(VLOOKUP(E34,WIP!$A$1:$M$1478,12,0),"-") -> - | X34: =IFERROR(VLOOKUP(E34,WIP!$A$1:$M$1478,13,0),"-") -> - | Y34: =E34 | Z34: =IFERROR(VLOOKUP(E34,WIP!$A$1:$K$1478,2,0),"-") -> - | AA34: =IFERROR(VLOOKUP(C34,Pack!$A$5:$G$1997,3,FALSE),"-") -> - | AB34: =IFERROR(VLOOKUP(E34,WIP!$A$1:$K$1478,11,0),"-") -> - | AC34: =IFERROR(VLOOKUP(E34,WIP!$A$1:$K$1478,7,0),"-") -> - | AD34: =IF(U34<13,J34,0) -> 0 | AE34: =IFERROR(AD34/AB34,"-") -> - | AG34: =IF(U34>13,J34,0) | AH34: =IFERROR(AG34/AB34,0) -> 0
A35: A | B35: =iferror(vlookup(C35,Source!$A$10:$O$1488,3,0),"-") -> - | E35: =iferror(vlookup(C35,Source!$A$10:$O$1488,2,0),"-") -> - | F35: =iferror(vlookup(C35,Source!$A$10:$O$1488,12,0),"-") -> - | G35: =IF(H35="B","BOX LABEL",+IF(AND(H35="I"),"IN HOUSE",+IF(AND(H35="S"),"SPECIAL",+IF(AND(H35="BP"),"BUG FREE",+IF(AND(H35="A"),"Pre Labeled","-"))))) -> - | H35: =iferror(vlookup(C35,Source!$A$10:$O$1488,11,0),"-") -> - | I35: =iferror(vlookup(C35,Source!$A$10:$O$1488,7,0),"-") -> - | J35: =IFERROR(_xlfn.FLOOR.MATH(VLOOKUP(C35, Conversion!$A$1:$G$1483,7,0)*D35*1.05,10),"-") -> - | K35: =if(G35="in house",D35*4,+if(G35="bottle label",D35*4,+if(or(G35="bottle"),G35*4,0))) -> 0 | L35: =if(G35="box label",D35,+IF(or(G35="in house"),D35,+if(or(G35="special"),D35,0))) -> 0 | M35: =iferror(vlookup(C35,Source!$A$10:$O$1488,14,0),"-") -> - | N35: =iferror(vlookup(C35,Source!$A$10:$O$1488,15,0),"-") -> - | O35: =iferror(vlookup(C35,Source!$A$10:$O$1488,5,0),0) -> 0 | P35: =if(O35>1,O35/6.5,"-") -> - | Q35: =if(O35>0,D35/O35*6.5,0) -> 0 | U35: =SUM(0.5,Q35)+SUM(U34) -> 14.5 | V35: =IFERROR(VLOOKUP(E35,WIP!$A$1:$S$1478,6,0),"-") -> - | W35: =IFERROR(VLOOKUP(E35,WIP!$A$1:$M$1478,12,0),"-") -> - | X35: =IFERROR(VLOOKUP(E35,WIP!$A$1:$M$1478,13,0),"-") -> - | Y35: =E35 -> - | Z35: =IFERROR(VLOOKUP(E35,WIP!$A$1:$K$1478,2,0),"-") -> - | AA35: =IFERROR(VLOOKUP(C35,Pack!$A$5:$G$1997,3,FALSE),"-") -> - | AB35: =IFERROR(VLOOKUP(E35,WIP!$A$1:$K$1478,11,0),"-") -> - | AC35: =IFERROR(VLOOKUP(E35,WIP!$A$1:$K$1478,7,0),"-") -> - | AD35: =IF(U35<13,J35,0) -> 0 | AE35: =IFERROR(AD35/AB35,"-") -> - | AG35: =IF(U35>13,J35,0) -> - | AH35: =IFERROR(AG35/AB35,0) -> 0
A36: B | B36: =iferror(vlookup(C36,Source!$A$10:$O$1488,3,0),"-") -> - | E36: =iferror(vlookup(C36,Source!$A$10:$O$1488,2,0),"-") -> - | F36: =iferror(vlookup(C36,Source!$A$10:$O$1488,12,0),"-") -> - | G36: =IF(H36="B","BOX LABEL",+IF(AND(H36="I"),"IN HOUSE",+IF(AND(H36="S"),"SPECIAL",+IF(AND(H36="BP"),"BUG FREE",+IF(AND(H36="A"),"Pre Labeled","-"))))) -> - | H36: =iferror(vlookup(C36,Source!$A$10:$O$1488,11,0),"-") -> - | I36: =iferror(vlookup(C36,Source!$A$10:$O$1488,7,0),"-") -> - | J36: =IFERROR(_xlfn.FLOOR.MATH(VLOOKUP(C36, Conversion!$A$1:$G$1483,7,0)*D36*1.05,10),"-") -> - | K36: =if(G36="in house",D36*4,+if(G36="bottle label",D36*4,+if(or(G36="bottle"),G36*4,0))) -> 0 | L36: =if(G36="box label",D36,+IF(or(G36="in house"),D36,+if(or(G36="special"),D36,0))) -> 0 | M36: =iferror(vlookup(C36,Source!$A$10:$O$1488,14,0),"-") -> - | N36: =iferror(vlookup(C36,Source!$A$10:$O$1488,15,0),"-") -> - | O36: =iferror(vlookup(C36,Source!$A$10:$O$1488,5,0),0) -> 0 | P36: =if(O36>1,O36/6.5,"-") -> - | Q36: =if(O36>0,D36/O36*6.5,0) -> 0 | U36: =SUM(0.5,Q36)+SUM(U35) -> 15 | V36: =IFERROR(VLOOKUP(E36,WIP!$A$1:$S$1478,6,0),"-") -> - | W36: =IFERROR(VLOOKUP(E36,WIP!$A$1:$M$1478,12,0),"-") -> - | X36: =IFERROR(VLOOKUP(E36,WIP!$A$1:$M$1478,13,0),"-") -> - | Y36: =E36 -> - | Z36: =IFERROR(VLOOKUP(E36,WIP!$A$1:$K$1478,2,0),"-") -> - | AA36: =IFERROR(VLOOKUP(C36,Pack!$A$5:$G$1997,3,FALSE),"-") -> - | AB36: =IFERROR(VLOOKUP(E36,WIP!$A$1:$K$1478,11,0),"-") -> - | AC36: =IFERROR(VLOOKUP(E36,WIP!$A$1:$K$1478,7,0),"-") -> - | AD36: =IF(U36<13,J36,0) -> 0 | AE36: =IFERROR(AD36/AB36,"-") -> - | AG36: =IF(U36>13,J36,0) -> - | AH36: =IFERROR(AG36/AB36,0) -> 0
